tests/64_threads/sample_23.in
64
o
62 S 101 5 112 480
32 S 102 1 171 971
23 S 105 3 179 460
28 S 106 7 140 85
20 S 108 1 119 854
33 S 109 1 114 995
30 B 110 9 156 787
20 C 108
8 S 115 2 190 297
15 S 116 5 139 208
41 B 118 8 108 331
17 S 119 7 155 573
63 S 121 2 114 655
37 S 122 4 137 973
21 S 125 8 184 620
17 S 126 0 148 469
8 B 129 9 133 570
51 S 131 4 191 812
22 S 132 9 146 462
44 B 135 0 128 10
59 B 136 4 156 392
12 S 137 8 187 814
33 C 109
59 C 136
39 B 143 8 142 26
22 S 144 8 193 87
12 C 137
17 C 119
8 C 129
31 B 153 1 155 604
49 S 154 7 105 322
31 B 157 7 167 884
39 S 158 5 131 759
23 S 159 8 152 840
16 B 162 4 191 337
20 C 108
45 B 165 5 145 783
41 S 166 5 127 471
48 B 168 6 142 728
38 S 169 8 164 39
20 C 108
12 S 171 3 106 271
19 B 172 2 130 629
28 S 173 4 149 986
49 B 174 2 126 161
44 C 135
30 B 176 9 171 961
62 B 177 6 143 775
12 B 178 2 162 171
18 S 179 4 150 461
50 B 180 2 192 481
31 C 153
4 S 183 1 159 813
12 S 184 8 114 922
62 S 185 5 173 509
52 S 186 4 162 445
60 B 187 9 101 344
48 B 188 3 156 267
9 B 189 3 127 429
40 S 190 8 168 717
39 C 143
61 S 192 9 150 634
62 S 193 3 145 329
49 B 194 0 111 775
46 S 195 1 171 468
36 S 196 9 158 114
60 B 197 5 139 295
8 B 198 7 104 947
40 S 199 3 133 340
54 B 200 4 102 771
26 B 202 3 130 388
37 B 204 2 107 712
36 S 205 6 176 426
43 S 206 4 137 209
33 S 207 5 193 786
36 C 205
20 C 108
59 S 210 8 149 84
8 S 211 5 114 95
32 C 102
59 C 136
56 B 214 1 170 73
45 C 165
62 S 216 1 125 405
23 C 159
1 B 218 5 172 321
4 S 219 2 175 327
28 B 220 6 121 20
8 C 198
63 S 223 5 106 311
13 S 224 1 115 755
36 C 205
62 C 177
12 B 228 8 112 639
61 S 230 5 100 127
43 S 231 6 152 393
41 C 166
61 B 233 2 134 295
35 B 236 7 158 595
55 B 237 5 101 950
15 S 238 1 185 902
56 B 239 6 139 215
34 B 240 0 120 540
41 B 241 4 180 24
16 C 162
31 S 243 3 122 280
54 C 200
50 B 245 9 149 928
47 S 247 9 131 920
62 S 248 5 182 963
33 S 249 8 198 34
33 S 250 0 149 435
54 S 251 2 162 296
34 C 240
20 C 108
4 C 183
20 C 108
27 S 256 2 173 35
36 B 257 2 115 470
6 B 258 9 179 569
52 C 186
18 C 179
16 B 262 6 130 955
11 S 263 2 104 808
15 S 264 7 142 194
43 B 265 7 200 379
49 B 266 4 155 932
25 S 267 5 123 892
38 B 268 8 149 810
10 S 269 4 178 538
46 B 271 0 168 278
20 B 272 1 112 957
37 C 122
54 B 274 5 176 648
15 C 264
21 S 276 7 185 440
6 S 277 3 168 528
43 B 278 0 136 723
58 S 279 2 103 76
9 B 280 3 165 917
5 S 281 9 156 501
43 C 206
37 B 283 2 142 260
63 S 285 8 176 750
10 B 286 2 157 621
44 C 135
9 B 288 7 135 311
56 C 214
11 S 290 4 160 663
5 S 291 2 115 574
31 B 292 9 195 756
19 S 293 8 194 439
9 C 189
62 S 296 3 182 951
12 C 228
1 B 298 8 199 936
46 S 299 3 166 312
20 B 300 5 164 564
3 B 301 2 169 468
57 S 302 4 110 118
4 S 303 7 191 696
11 B 304 1 152 71
6 B 305 4 154 724
23 B 306 7 174 81
14 S 307 1 142 143
42 S 308 0 175 929
12 C 228
34 B 310 9 129 439
56 B 311 7 170 870
7 S 312 9 161 905
37 B 313 1 188 643
46 S 314 8 175 333
7 C 312
1 B 316 9 117 787
56 B 317 8 183 896
50 S 318 5 170 17
55 B 319 3 165 447
12 C 171
52 B 321 3 116 586
21 C 276
61 C 230
4 S 324 2 184 558
10 C 269
42 S 326 6 105 353
36 B 327 9 181 200
22 S 328 6 194 568
42 S 329 2 152 988
7 B 330 3 141 142
29 S 331 6 172 479
2 S 332 5 156 683
62 S 333 4 147 666
40 B 334 9 184 807
28 B 335 6 184 810
62 S 336 9 157 849
27 C 256
26 S 338 8 111 683
32 B 339 9 143 460
30 C 110
34 C 310
30 C 176
16 B 343 0 101 918
13 B 344 4 180 580
9 S 345 8 135 624
49 S 346 2 171 498
31 S 347 4 155 669
13 C 224
38 B 349 7 175 793
12 S 350 6 195 876
59 S 351 6 116 979
21 B 352 9 152 230
61 B 353 8 161 135
46 B 354 6 126 454
54 S 355 5 115 998
47 C 247
29 C 331
23 S 358 3 159 900
5 S 359 3 179 578
36 C 257
38 C 169
48 S 362 0 175 312
33 B 363 4 157 521
23 B 364 8 117 544
21 S 365 2 119 871
31 C 347
60 S 368 3 149 531
35 C 236
44 B 370 6 175 840
34 B 371 0 196 686
35 S 372 5 166 761
51 S 373 3 200 875
26 B 374 6 173 228
32 S 375 1 152 953
14 B 376 8 110 168
30 B 377 9 180 28
61 S 378 1 119 569
36 B 379 1 128 39
60 B 380 8 195 896
50 B 381 6 122 325
52 B 382 0 166 668
62 C 296
19 B 384 1 144 998
35 S 385 6 112 282
48 B 386 2 148 101
55 S 387 8 181 59
56 S 388 8 194 699
40 S 389 1 180 96
41 C 118
1 S 391 2 192 457
19 C 384
25 S 393 9 182 422
5 S 394 1 129 26
16 B 395 2 128 65
11 S 396 7 147 81
50 B 397 4 168 386
62 S 398 9 174 607
59 C 210
5 B 400 5 135 222
12 S 401 3 200 150
28 B 402 9 119 420
63 C 223
36 C 257
33 C 249
58 S 406 6 191 217
52 S 407 8 115 721
7 S 408 1 198 676
44 B 409 6 129 325
42 S 410 0 167 53
12 C 171
51 C 131
32 S 413 3 159 408
55 S 414 1 184 330
50 S 415 1 182 89
47 S 416 4 110 349
52 S 417 3 134 602
36 B 418 1 102 820
57 S 419 6 145 444
18 B 420 1 103 394
17 C 119
26 B 422 8 187 556
32 S 423 9 177 852
8 C 211
59 S 425 2 128 385
38 B 426 3 194 45
30 S 427 0 163 917
55 C 414
33 B 429 4 181 498
49 S 430 0 180 94
51 B 431 3 184 911
35 C 236
28 B 433 7 154 492
11 B 434 8 173 477
8 C 198
8 S 436 2 124 500
7 B 437 5 182 440
3 B 438 0 130 113
2 B 439 4 121 895
49 C 266
51 B 441 8 120 373
41 B 442 8 171 744
35 S 443 4 159 463
52 B 444 5 166 594
12 C 171
35 B 446 2 111 148
37 C 283
48 S 448 0 133 30
14 S 449 1 102 227
16 C 343
16 B 451 1 106 982
15 C 238
61 B 453 0 157 430
51 S 454 9 132 395
47 C 247
29 C 331
26 B 457 1 157 414
4 B 458 2 180 639
14 S 459 0 193 788
29 S 460 5 169 109
59 C 136
6 C 258
43 C 265
40 C 389
18 B 465 0 175 691
28 S 466 5 162 321
10 B 467 0 168 93
58 S 468 3 129 864
19 B 469 2 139 141
36 S 470 8 126 544
63 C 121
7 C 408
39 B 473 6 116 573
30 B 474 6 160 498
16 S 475 9 103 464
57 C 302
52 S 477 1 180 959
41 B 478 5 135 124
43 S 479 4 196 63
58 S 480 5 181 562
26 S 481 4 153 116
63 S 482 7 173 330
61 C 192
63 S 484 0 106 431
36 S 485 6 128 793
3 C 438
34 C 310
11 C 304
25 B 489 4 165 349
45 C 165
15 S 491 5 157 708
55 B 492 9 135 801
14 S 493 5 144 623
54 S 494 5 136 525
49 C 194
10 S 496 4 130 621
32 B 497 5 138 486
3 S 498 4 188 599
37 S 499 2 164 675
1 C 316
45 C 165
9 S 502 6 106 495
58 S 503 5 189 393
26 B 504 9 158 745
13 B 505 8 200 36
16 C 475
4 C 324
3 S 508 9 189 461
25 C 489
4 S 510 4 164 293
17 B 511 9 173 923
22 S 512 1 113 110
34 B 513 8 189 173
3 S 514 8 170 187
30 B 515 0 103 749
3 C 498
6 S 517 5 103 140
10 B 518 7 167 273
4 B 519 5 196 198
29 B 520 1 129 29
45 S 521 9 160 659
4 C 519
1 S 523 5 139 81
39 B 524 1 108 661
62 S 525 8 102 522
18 B 526 4 180 91
41 B 527 8 185 457
26 B 528 7 193 492
50 B 529 9 101 482
43 C 265
32 C 102
59 C 351
40 S 533 3 144 252
3 C 438
30 C 377
31 B 536 8 152 236
35 S 537 3 121 655
60 S 538 9 145 809
1 S 539 5 117 869
35 B 540 2 119 384
16 S 541 5 131 750
3 C 514
63 C 285
1 B 544 4 179 230
56 C 311
29 C 460
4 B 547 7 150 389
37 B 548 7 105 585
16 S 549 9 153 506
45 S 550 3 106 554
61 S 551 9 107 896
46 C 314
61 S 553 9 141 258
47 S 554 6 119 785
9 B 555 9 134 133
50 C 245
22 B 557 4 134 815
19 S 558 3 106 953
59 S 559 4 105 126
58 C 279
9 B 561 8 170 662
30 C 427
41 C 241
44 S 564 9 111 633
63 S 565 0 119 624
27 B 567 9 180 43
46 S 568 5 187 335
5 C 291
31 B 570 9 143 980
55 S 571 8 123 640
7 C 408
43 B 573 4 188 286
41 B 574 7 146 331
29 S 576 0 167 393
42 C 410
46 B 578 0 124 315
16 C 262
28 B 580 7 177 379
50 B 581 7 128 922
22 B 582 2 185 986
13 B 583 1 143 169
51 S 584 1 120 337
10 B 585 1 174 743
29 B 586 5 195 882
49 B 587 1 171 17
3 B 588 3 183 199
28 C 580
45 C 521
48 S 591 3 131 305
59 S 592 3 189 291
44 C 370
9 S 594 6 115 890
1 C 298
47 C 247
43 C 573
29 S 598 5 181 960
39 S 599 2 104 153
36 S 600 7 200 596
13 C 224
13 B 602 0 180 753
6 B 603 9 180 966
51 S 604 7 131 991
10 C 467
4 B 606 2 136 539
1 B 607 9 111 492
4 B 608 9 180 23
47 S 609 0 198 813
40 B 610 4 181 721
63 S 611 6 104 284
16 S 612 2 125 409
52 C 382
62 B 614 2 113 776
27 B 615 8 175 163
14 B 616 1 142 821
13 S 617 5 182 975
28 S 618 0 168 428
34 C 371
17 S 620 2 151 751
27 C 256
33 S 622 6 144 924
46 B 623 9 148 435
34 B 624 7 161 558
50 C 397
20 B 626 5 141 664
5 S 627 5 110 350
55 S 628 2 108 662
8 C 115
58 C 406
44 B 631 7 156 852
61 S 632 3 128 485
20 C 272
10 C 269
40 C 533
53 B 636 7 176 714
61 S 637 3 114 134
19 S 638 9 170 27
50 C 581
0 S 640 9 123 401
15 C 491
