tests/64_threads/sample_24.in
64
o
41 B 102 6 112 908
24 B 104 3 100 385
53 S 105 9 105 397
33 B 108 0 105 97
25 B 110 1 144 723
27 S 111 7 117 132
48 B 112 5 163 515
45 S 113 2 194 962
7 B 114 6 175 456
29 S 116 8 144 392
11 S 118 5 197 627
21 B 119 2 198 252
7 B 120 6 126 323
15 B 121 1 157 784
30 S 123 8 175 257
58 B 124 4 174 689
45 C 113
48 B 127 8 119 806
56 S 128 1 117 542
46 S 129 3 119 165
7 C 114
14 B 131 2 104 407
8 B 134 9 118 924
26 S 135 8 176 764
35 S 136 5 155 362
28 S 137 3 108 868
41 C 102
28 C 137
25 S 140 6 121 212
18 B 141 4 189 531
52 B 142 4 140 168
30 C 123
29 B 145 4 147 781
35 S 149 1 142 740
0 B 150 4 153 391
53 C 105
62 B 152 4 129 484
24 C 104
39 B 155 8 123 745
62 C 152
13 B 157 0 115 310
14 C 131
0 C 150
35 C 136
37 B 162 7 108 775
29 C 116
45 C 113
34 S 165 6 198 646
5 B 166 1 196 350
25 S 167 1 136 308
14 S 168 5 127 165
38 S 170 8 184 222
21 B 171 6 132 535
15 B 172 0 107 675
13 B 174 6 135 381
4 B 175 7 155 387
18 C 141
32 S 177 5 121 183
54 B 178 0 157 589
8 B 179 9 126 679
17 B 180 6 166 98
31 B 181 2 183 663
9 B 182 6 187 43
52 C 142
6 S 184 0 105 252
57 B 185 6 107 956
35 B 186 6 151 34
61 S 187 1 188 576
17 C 180
61 C 187
37 B 190 7 143 762
21 C 171
5 C 166
56 S 193 1 174 767
19 S 194 8 177 223
3 S 195 9 158 343
0 B 196 6 157 613
52 B 197 2 174 249
30 S 198 7 150 748
25 S 199 7 157 100
57 C 185
27 B 201 0 163 78
35 B 202 6 106 498
46 C 129
24 S 205 3 194 467
55 S 206 5 186 687
16 S 207 6 196 499
4 C 175
9 S 210 3 138 957
57 B 211 8 143 937
60 B 212 5 146 879
12 S 213 8 162 66
39 S 214 7 139 997
16 B 216 7 129 646
30 B 217 3 133 910
39 C 155
8 C 179
56 C 193
36 B 221 9 148 536
48 B 222 0 155 567
29 B 223 1 141 323
38 S 224 8 104 582
46 S 225 7 139 658
23 S 227 7 173 990
4 S 228 6 140 491
0 C 150
52 C 197
32 C 177
43 S 232 2 168 909
40 B 233 5 156 18
30 C 198
0 B 235 5 117 447
36 B 236 3 190 651
44 S 238 4 191 24
56 C 193
5 B 240 5 154 203
17 S 242 9 108 516
18 C 141
13 C 174
11 B 246 0 175 158
63 B 247 2 135 137
56 S 248 3 156 777
28 B 250 0 173 247
34 B 251 3 153 547
3 C 195
29 C 223
16 C 207
11 B 256 0 162 414
63 C 247
35 B 258 4 131 250
45 C 113
21 C 119
35 B 261 0 132 600
31 S 262 3 163 23
21 S 264 5 117 109
57 B 265 6 159 898
39 C 214
3 B 267 1 102 794
52 C 142
4 S 269 7 192 707
58 S 270 5 155 241
26 S 271 9 178 637
56 C 248
21 S 273 1 141 55
31 B 274 4 129 778
17 C 242
0 C 150
62 S 277 6 180 213
28 B 278 1 184 684
45 S 279 4 131 997
36 S 280 4 184 945
46 B 281 0 172 690
21 S 282 2 194 737
31 S 283 5 115 214
50 S 284 0 108 475
13 B 285 6 163 526
58 B 286 0 107 667
6 B 287 3 107 456
20 S 288 5 168 556
24 S 289 3 110 446
19 S 290 2 199 628
48 B 291 8 144 126
51 B 292 7 125 326
1 S 293 6 124 416
5 C 240
63 B 295 6 129 840
55 C 206
39 C 155
14 B 298 1 178 186
17 S 299 7 150 452
59 B 300 8 115 560
13 C 157
28 S 302 3 183 31
24 S 303 5 113 631
23 B 304 7 185 809
44 B 305 0 170 955
31 C 181
26 C 271
6 C 184
52 S 309 6 118 679
27 B 310 8 185 593
24 B 311 1 154 161
43 B 312 8 100 520
14 C 298
37 S 314 0 128 353
54 B 315 1 172 197
30 C 217
36 C 236
51 C 292
59 S 319 7 190 657
56 B 320 0 187 47
43 B 321 7 179 394
60 B 322 4 125 746
5 C 166
38 B 324 8 159 987
29 B 325 7 166 906
50 B 326 4 115 200
28 B 327 2 143 684
46 S 328 2 158 900
34 S 329 3 128 976
24 B 330 4 196 396
60 B 331 2 122 457
12 B 332 2 150 376
18 S 333 8 168 64
7 C 120
60 S 335 1 102 793
46 B 336 5 161 1000
11 S 337 8 160 792
48 C 127
44 S 339 0 155 891
33 S 340 7 121 97
36 C 236
60 C 335
13 C 174
57 C 185
33 C 108
26 C 135
13 C 157
58 B 349 6 123 685
32 S 350 0 116 176
38 B 351 4 181 805
61 S 352 1 132 932
8 S 353 2 130 454
37 S 354 0 110 418
28 B 355 4 159 481
36 B 356 8 110 176
61 C 187
8 B 358 0 147 484
43 B 359 4 197 959
43 C 312
62 C 152
11 C 337
12 S 363 1 114 482
33 C 108
16 B 365 8 197 53
1 B 366 8 166 798
40 B 367 7 166 992
62 B 368 2 159 588
18 S 369 9 176 234
37 C 162
24 B 371 6 117 245
59 C 319
9 B 373 4 198 643
52 S 374 1 193 217
37 B 375 6 165 83
35 C 186
41 B 377 2 175 633
20 B 379 5 171 387
40 B 380 0 140 727
27 C 310
39 S 382 9 119 256
54 S 383 4 197 46
28 B 384 4 140 378
48 B 385 6 158 637
36 C 221
28 S 387 7 148 188
36 C 356
13 B 389 6 190 595
38 B 390 8 142 951
50 C 284
54 C 315
1 S 393 5 166 899
26 B 394 2 183 682
41 C 102
60 C 335
52 B 397 3 148 223
61 S 398 4 163 40
58 S 399 3 186 740
12 B 400 6 155 827
20 S 402 0 147 559
10 S 403 1 144 852
13 S 404 8 112 224
55 B 405 2 153 119
3 B 406 9 162 139
36 S 407 2 154 992
38 B 408 6 117 305
40 B 409 1 187 388
34 B 410 8 132 985
57 S 411 0 191 958
39 C 214
48 S 413 8 189 313
62 C 277
10 B 415 7 151 108
23 S 416 3 179 963
9 S 417 7 186 249
36 B 418 5 190 670
24 S 419 2 119 662
58 S 420 0 110 205
39 S 421 4 103 112
9 S 422 6 142 340
55 C 405
54 S 424 4 184 549
32 S 425 2 131 283
11 B 426 2 121 699
26 S 427 6 107 647
13 B 428 4 111 97
48 C 127
57 B 431 7 187 85
63 C 295
17 C 180
32 B 434 0 105 34
1 S 435 1 138 630
41 B 436 1 196 787
5 B 437 5 183 930
58 C 286
22 S 439 7 131 415
45 B 440 2 149 626
3 S 441 7 174 648
57 C 185
17 B 443 2 187 766
8 B 444 7 156 318
55 S 445 7 185 881
5 S 446 6 170 244
30 B 447 6 164 496
0 S 448 8 121 96
22 B 449 3 156 328
29 B 450 6 122 195
31 B 451 2 196 299
46 C 336
10 S 453 3 174 606
10 S 454 4 152 767
25 C 167
0 C 196
43 C 359
63 C 295
22 C 439
28 B 460 4 138 252
6 C 184
27 B 462 5 110 879
0 C 448
32 C 425
4 B 465 9 199 904
44 B 466 2 182 583
33 B 467 4 120 408
40 S 468 9 157 477
3 S 469 9 106 321
15 B 470 1 148 51
56 S 471 6 164 122
63 B 472 2 137 529
20 B 473 6 158 54
13 S 474 2 123 184
51 B 475 2 192 978
63 B 476 9 188 662
55 B 477 7 140 407
56 S 478 8 130 39
58 C 286
26 S 481 4 192 351
17 C 180
41 C 102
23 S 484 0 158 966
54 C 315
29 S 486 6 119 839
31 B 487 6 182 984
17 B 489 2 128 175
3 S 490 9 109 84
62 C 152
44 S 492 1 175 473
41 B 493 5 183 361
20 C 402
63 S 495 1 133 411
54 B 496 9 180 68
39 S 497 4 138 597
13 C 174
48 C 413
60 S 500 7 127 318
23 B 501 4 129 1000
52 C 309
50 C 284
38 C 324
33 C 108
42 B 506 2 162 365
63 S 507 6 105 389
1 C 393
54 C 496
38 B 510 7 188 782
7 B 511 3 144 524
51 C 292
16 B 513 6 146 373
42 S 514 8 143 761
35 C 261
29 B 516 4 107 943
55 S 517 2 138 691
49 S 518 7 189 631
33 S 519 3 173 751
62 B 520 8 151 237
16 C 365
51 B 522 5 148 193
46 C 328
32 C 350
20 S 525 6 122 607
48 C 112
27 C 310
19 S 528 0 162 775
54 B 529 4 161 209
55 C 445
0 B 531 9 107 164
54 C 424
8 B 533 0 196 937
45 C 279
2 B 535 5 108 461
49 C 518
21 S 537 4 119 394
9 C 182
35 C 258
43 C 321
52 S 541 0 137 114
63 S 542 4 126 621
16 S 543 9 109 559
19 C 528
9 B 545 6 117 282
13 B 546 8 133 315
27 B 547 4 184 136
27 S 548 0 177 11
5 B 549 8 143 688
26 S 550 1 160 274
2 B 551 7 177 352
60 B 552 6 162 584
11 S 553 2 127 671
37 B 554 3 165 139
26 S 555 2 133 499
36 C 418
43 S 557 7 100 890
16 C 216
56 C 128
26 B 561 6 148 721
51 B 562 9 110 775
19 S 563 9 132 608
58 B 564 1 194 72
45 C 440
42 S 566 1 175 199
6 B 567 1 195 798
11 B 568 9 175 509
30 B 569 2 177 588
45 S 570 8 116 464
3 S 571 9 146 485
52 B 572 6 147 639
55 S 573 8 181 959
53 B 574 1 134 72
47 B 575 5 197 683
49 S 576 0 114 779
16 C 543
25 S 578 3 133 48
5 S 579 1 182 716
36 C 280
17 S 581 3 113 380
61 B 582 2 182 349
38 B 583 0 200 227
28 C 355
22 B 585 5 129 219
24 C 311
25 C 167
35 B 588 9 149 991
30 C 123
33 C 340
54 B 591 3 128 463
39 B 592 8 150 650
29 S 593 0 184 696
13 B 594 9 186 906
6 B 595 4 138 802
33 C 519
13 S 597 4 189 210
32 B 598 3 118 144
29 B 599 2 192 862
53 S 600 5 119 651
17 S 601 2 151 618
39 B 602 1 160 186
8 B 603 5 118 586
26 S 604 5 176 317
59 C 300
25 S 606 9 178 548
20 B 607 2 135 559
12 B 608 7 198 214
10 S 609 7 103 553
54 B 610 6 128 972
25 B 611 8 145 309
53 C 105
16 C 216
35 S 614 2 184 412
38 C 390
50 S 616 5 108 864
43 C 557
7 S 618 9 151 713
7 C 120
9 C 182
53 B 621 6 165 993
13 C 404
8 S 623 9 200 380
55 B 624 7 200 38
35 C 588
15 C 470
52 S 627 3 147 566
36 C 236
9 B 629 5 192 620
50 S 630 8 100 859
44 C 466
21 S 632 7 153 140
0 B 633 7 193 127
19 C 194
29 C 486
58 B 636 6 146 263
39 B 637 0 153 111
52 B 638 0 170 500
29 C 116
46 S 640 1 171 755
31 B 641 7 182 25
22 B 642 6 150 127
22 C 449
